Workbook

Sheet 00 Contents
B2: 00 — ALPHABET (GOOGL) RESEARCH DATA PACK
B3: Compiled September 10, 2026; share prices and peer multiples refreshed October 16, 2026. All figures $ millions unless noted. Personal hobby project by Mohammad Ahmadi, for informational and educational purposes only; not investment advice. Model outputs are assumption-dependent. Use at your own risk. Methodology, sources, assumptions and revisions are documented within the file.
B5: Sheet | C5: What it holds and why it sits here
B6: PART 1 - THE EVIDENCE: what Alphabet actually filed
B7: 01 Income Statement | C7: FY2023-FY2025 plus TTM Mar'26 and TTM Jun'26, with a derived-vs-filed flag. The top line of the whole argument.
B8: 02 Quarterly | C8: Q1 and Q2 2026 versus prior year. Isolates the ex-gain other-income line where the distortion first shows.
B9: 03 Segments | C9: ="Revenue, operating income, growth and margin by segment. Establishes that ~"&TEXT('02 Quarterly'!$D$29,"0")&"% operating margin is the real earning power." -> Revenue, operating income, growth and margin by segment. Establishes that ~34% operating margin is the real earning power.
B10: 04 Balance Sheet | C10: FY2023-Jun'26, PP&E corrected to filed figures. Holds the equity-securities portfolio that creates the gain.
B11: 05 Capital Structure | C11: The June 2026 raise as filed, share counts, preferred dividend. The denominator of every per-share figure.
B12: PART 2 - THE DISTORTION: why reported earnings overstate the business
B13: 06 Core EPS Bridge | C13: THE PIVOT OF THE PACK. Strips the equity-securities gain, tax-effects it, restates EPS. Reported becomes core here.
B14: 07 Consensus | C14: ="Consensus is GAAP-basis: FY2026 EPS of "&TEXT('07 Consensus'!$C$6,"0.00")&" implies a "&TEXT('07 Consensus'!$C$9/100,"0.0%")&" net margin against a "&TEXT('07 Consensus'!$C$11/100,"0.0%")&" Q2 operating margin because it books the H1'26 marks. The reported "&TEXT('11 Valuation'!$C$11,"0.0")&"x flatters the stock on a screen; it is not a consensus error." -> Consensus is GAAP-basis: FY2026 EPS of 20.60 implies a 50.8% net margin against a 34.0% Q2 operating margin because it books the H1'26 marks. The reported 17.1x flatters the stock on a screen; it is not a consensus error.
B15: PART 3 - WHAT DRIVES CASH: the capex question
B16: 08 PPE and Depreciation | C16: ="Asset classes, useful lives, and the "&TEXT('08 PPE and Depreciation'!$C$24,"#,##0")&" sitting in assets NOT YET IN SERVICE - the future depreciation charge." -> Asset classes, useful lives, and the 122,814 sitting in assets NOT YET IN SERVICE - the future depreciation charge.
B17: 09 Cash Flow | C17: Annual and quarterly, including the first negative FCF quarter. Where the capex actually lands.
B18: 10 Guidance and Quotes | C18: Capex guidance trail and verbatim management quotes. What management says about when capex plateaus.
B19: PART 4 - THE VERDICT: what it is worth
B20: 11 Valuation | C20: ="Reported versus core multiples at "&TEXT('11 Valuation'!$C$6,"$0.00")&". "&TEXT('11 Valuation'!$C$11,"0.0")&"x reported, "&TEXT('11 Valuation'!$C$12,"0.0")&"x core - the gap Parts 2 and 3 explain." -> Reported versus core multiples at $340.59. 17.1x reported, 33.0x core - the gap Parts 2 and 3 explain.
B21: 12 Peers | C21: Mega-cap comp table. Shows negative FCF is a cohort feature, not a GOOGL defect.
B22: 13 EPIC Ranking | C22: EPIC factor ranking: Exceeds materiality, Probably occurs, I can forecast, Consensus gap; totals are live and feed the research agenda.
B23: PART 5 - THE FORWARD MODEL: what FCF normalises to
B24: 14 Model Cover | C24: Explains the forward-model architecture, source links, scenario design and scope.
B25: 15 Assumptions | C25: Central model inputs for growth, margin, capex, depreciation, tax, financing and balance-sheet drivers.
B26: 16 Scenarios | C26: One visible switch drives Base, Best and Worst operating assumptions.
B27: 17 Model | C27: Integrated revenue, earnings, depreciation and cash-flow forecast through FY2030E.
B28: 18 Balance Sheet | C28: Live balance-sheet, cash, debt and equity roll-forwards following the active scenario, with eight checks.
B29: 19 Model Summary | C29: Scenario-linked operating summary and narrative interpretation.
B30: 20 DCF Valuation | C30: Three-scenario unlevered FCFF valuation at WACC, equity bridge, sensitivity and nineteen live checks.
B31: 21 Reverse DCF | C31: What the price assumes: single-lever break-evens, layered levers and validation against the earlier model state. Static tables must be refreshed after any model change.
B32: PART 6 - VISUAL ANALYSIS: data first, charts second
B33: 22 Earnings Quality | C33: Reported versus core EPS and P/E, with the live source table printed above the charts.
B34: 23 Growth and Mix | C34: Revenue, operating income and segment mix from FY2023 through FY2030E.
B35: 24 Cash and Margins | C35: Operating cash flow, capex, FCF, depreciation and margin paths.
B36: 25 Peers and Priorities | C36: Peer capital-efficiency map and EPIC research-priority ranking.
B37: PART 7 - PROVE IT: verification and provenance
B38: 26 Pack Audit | C38: =(COUNTIF('26 Pack Audit'!$F:$F,"TIES")+COUNTIF('26 Pack Audit'!$F:$F,"DOES NOT TIE"))&" live cross-sheet checks re-deriving key research-pack figures from source cells." -> 26 live cross-sheet checks re-deriving key research-pack figures from source cells.
B39: 27 Model Audit | C39: =(COUNTIF('27 Model Audit'!$F:$F,"TIES")+COUNTIF('27 Model Audit'!$F:$F,"DOES NOT TIE"))&" live checks re-deriving the model from the original pack sources." -> 71 live checks re-deriving the model from the original pack sources.
B40: 28 Sources | C40: Every cited URL, with verification status and quality classification.
B41: 29 Change Log | C41: Chronological record of workbook changes, audit findings and repairs.
B42: THE ONE STORY THIS PACK TELLS
...

Sheet 01 Income Statement
B2: 01 — CONSOLIDATED INCOME STATEMENT
B3: $ millions except per-share. TTM Jun'26 is DERIVED as FY2025 + H1'26 - H1'25.
B5: Line item | C5: FY2023 | D5: FY2024 | E5: FY2025 | F5: TTM Mar'26 | G5: TTM Jun'26 | H5: Basis
B6: Total revenues | C6: 307394 | D6: 350018 | E6: 402836 | F6: 422498 | G6: =E6+'02 Quarterly'!D7+'02 Quarterly'!D23-'02 Quarterly'!C7-'02 Quarterly'!C23 -> 445866 | H6: filed / derived TTM
B7: Cost of revenues | C7: 133332 | D7: 146306 | E7: 162535 | F7: 167445 | G7: =E7+'02 Quarterly'!D8+'02 Quarterly'!D24-'02 Quarterly'!C8-'02 Quarterly'!C24 -> 174349 | H7: filed / derived TTM
B8: Research and development | C8: 45427 | D8: 49326 | E8: 61087 | F8: 64563 | G8: 68974 | H8: filed / derived TTM
B9: Sales and marketing | C9: 27917 | D9: 27808 | E9: 28693 | G9: 31429 | H9: filed / derived TTM
B10: General and administrative | C10: 16425 | D10: 14188 | E10: 21482 | G10: 23486 | H10: filed / derived TTM
B11: Total costs and expenses | C11: =C7+C8+C9+C10 -> 223101 | D11: =D7+D8+D9+D10 -> 237628 | E11: =E7+E8+E9+E10 -> 273797 | F11: 284369 | G11: =G7+G8+G9+G10 -> 298238 | H11: filed / derived TTM
B12: Income from operations | C12: =C6-C11 -> 84293 | D12: =D6-D11 -> 112390 | E12: =E6-E11 -> 129039 | F12: =F6-F11 -> 138129 | G12: =G6-G11 -> 147628 | H12: filed / derived TTM
B13: Operating margin % | C13: =C12/C6*100 -> 27.42181 | D13: =D12/D6*100 -> 32.109777 | E13: =E12/E6*100 -> 32.032639 | F13: =F12/F6*100 -> 32.693409 | G13: =G12/G6*100 -> 33.110396 | H13: calc
B14: Other income (expense), net | C14: 1424 | D14: 7425 | E14: 29787 | F14: 56320 | G14: =E14+'02 Quarterly'!D12+'02 Quarterly'!D30-'02 Quarterly'!C12-'02 Quarterly'!C30 -> 151641 | H14: filed / derived TTM
B15: Income before taxes | C15: =C12+C14 -> 85717 | D15: =D12+D14 -> 119815 | E15: =E12+E14 -> 158826 | F15: =F12+F14 -> 194449 | G15: =G12+G14 -> 299269 | H15: filed / derived TTM
B16: Provision for income taxes | C16: 11922 | D16: 19697 | E16: 26656 | F16: 34241 | G16: =E16+'02 Quarterly'!D15+'02 Quarterly'!D34-'02 Quarterly'!C15-'02 Quarterly'!C34 -> 55064 | H16: filed / derived TTM
B17: Effective tax rate % | C17: =C16/C15*100 -> 13.90856 | D17: =D16/D15*100 -> 16.439511 | E17: =E16/E15*100 -> 16.783146 | F17: =F16/F15*100 -> 17.609245 | G17: =G16/G15*100 -> 18.3995 | H17: calc
B18: Net income | C18: =C15-C16 -> 73795 | D18: =D15-D16 -> 100118 | E18: =E15-E16 -> 132170 | F18: =F15-F16 -> 160208 | G18: =G15-G16 -> 244205 | H18: filed / DERIVED TTM consolidated NI; see common-income note
B19: Diluted EPS ($) | C19: 5.8 | D19: 8.04 | E19: 10.81 | F19: 13.11 | G19: 19.93 | H19: ="DERIVED from filed: FY2025 "&TEXT($E$19,"0.00")&" + H1'26 "&TEXT('06 Core EPS Bridge'!$J$13,"0.00")&" - H1'25 "&TEXT('06 Core EPS Bridge'!$F$13+'06 Core EPS Bridge'!$H$13,"0.00") -> DERIVED from filed: FY2025 10.81 + H1'26 14.24 - H1'25 5.12
B20: Diluted weighted-avg shares | C20: 12722 | D20: 12447 | E20: 12230 | F20: 12217 | G20: =E20+'05 Capital Structure'!C16-'05 Capital Structure'!C21 -> 12259 | H20: DERIVED TTM = FY2025 + H1'26 - H1'25, the same roll as TTM EPS
B22: Notes and caveats
B23: • TTM (Jun'26) columns are DERIVED as FY2025 + H1 2026 - H1 2025 from filed statements. They are not a reported figure.
B24: • RESOLVED 2026-09-22: derived TTM consolidated net income is 244,205. The Q2 2026 10-Q reports H1'26 net income of 174,771 but only 174,685 available to common stockholders after 86 of preferred dividends. On the common-income basis, FY2025 132,170 + H1'26 174,685 - H1'25 62,736 = 244,119, effectively the provider's 244,120 after rounding. Keep row 18 as consolidated net income; per-share work must deduct preferred dividends separately.
B25: ="• TTM diluted EPS of "&TEXT($G$19,"0.00")&" is as-reported by the data provider. A TTM EPS cannot be built by summing weighted-average share counts." -> • TTM diluted EPS of 19.93 is as-reported by the data provider. A TTM EPS cannot be built by summing weighted-average share counts.
B26: ="• FY2025 G&A jumped "&"("&TEXT($E$10,"#,##0")&" vs "&TEXT($D$10,"#,##0")&")"&" partly on the EUR 2.95B EU ad-tech fine booked in Q3 2025 plus legal charges." -> • FY2025 G&A jumped (21,482 vs 14,188) partly on the EUR 2.95B EU ad-tech fine booked in Q3 2025 plus legal charges.
B27: • S&M / G&A not separately pulled for TTM Mar'26; combined SG&A for that period was 52,361.

Sheet 02 Quarterly
B2: 02 — QUARTERLY INCOME STATEMENT
B3: $ millions except per-share.
B5: Q1 2026 vs Q1 2025
B6: Line item | C6: Q1'25 | D6: Q1'26
B7: Revenue | C7: 90234 | D7: 109896
B8: Cost of revenue | C8: 36361 | D8: 41271
B9: Operating expenses | C9: 23267 | D9: 28929
B10: Income from operations | C10: =C7-C8-C9 -> 30606 | D10: =D7-D8-D9 -> 39696
B11: Operating margin % | C11: =C10/C7*100 -> 33.918479 | D11: =D10/D7*100 -> 36.121424
B12: Other income (expense), net | C12: 11183 | D12: 37716
B13: of which: gain on equity securities, net | C13: 9758 | D13: 36915
B14: Pretax income | C14: =C10+C12 -> 41789 | D14: =D10+D12 -> 77412
B15: Income tax | C15: 7249 | D15: 14834
B16: Net income | C16: =C14-C15 -> 34540 | D16: =D14-D15 -> 62578
B17: Diluted EPS reported ($) | C17: 2.81 | D17: 5.11
B18: Diluted EPS CORE ($) | C18: ='06 Core EPS Bridge'!F12 -> 2.1829941 | D18: ='06 Core EPS Bridge'!G12 -> 2.7304421
B19: Diluted shares | C19: 12291 | D19: 12238
B21: Q2 2026 vs Q2 2025
B22: Line item | C22: Q2'25 | D22: Q2'26 | E22: YoY %
B23: Revenue | C23: 96428 | D23: 119796 | E23: =(D23/C23-1)*100 -> 24.233625
B24: Cost of revenue | C24: 39039 | D24: 45943 | E24: =(D24/C24-1)*100 -> 17.684879
B25: Research and development | C25: 13808 | D25: 18219 | E25: =(D25/C25-1)*100 -> 31.945249
B26: Sales and marketing | C26: 7101 | D26: 8403 | E26: =(D26/C26-1)*100 -> 18.335446
B27: General and administrative | C27: 5209 | D27: 6461 | E27: =(D27/C27-1)*100 -> 24.035323
B28: Income from operations | C28: =C23-C24-C25-C26-C27 -> 31271 | D28: =D23-D24-D25-D26-D27 -> 40770 | E28: =(D28/C28-1)*100 -> 30.376387
B29: Operating margin % | C29: =C28/C23*100 -> 32.429377 | D29: =D28/D23*100 -> 34.032856
B30: Other income (expense), net | C30: 2662 | D30: 97983
B31: of which: gain on equity securities | C31: 1286 | D31: 99031
B32: other income EX-GAIN | C32: =C30-C31 -> 1376 | D32: =D30-D31 -> -1048
B33: Pretax income | C33: =C28+C30 -> 33933 | D33: =D28+D30 -> 138753
B34: Income tax | C34: 5737 | D34: 26560
B35: Effective tax rate % | C35: =C34/C33*100 -> 16.906846 | D35: =D34/D33*100 -> 19.141928
B36: Net income | C36: =C33-C34 -> 28196 | D36: =D33-D34 -> 112193 | E36: =(D36/C36-1)*100 -> 297.90396
B37: Diluted EPS reported ($) | C37: 2.31 | D37: 9.11 | E37: =(D37/C37-1)*100 -> 294.37229
B38: Diluted EPS CORE ($) | C38: ='06 Core EPS Bridge'!H12 -> 2.2282391 | D38: ='06 Core EPS Bridge'!I12 -> 2.7588358 | E38: =(D38/C38-1)*100 -> 23.81238
B39: Diluted shares | C39: 12198 | D39: 12309 | E39: =(D39/C39-1)*100 -> 0.90998524
B41: Notes and caveats
B42: • Q1'26 quarterly figures are as filed. Diluted EPS CORE rows are DERIVED (see '06 Core EPS Bridge').
B43: ="• THE EX-GAIN LINE: other income excluding the securities gain went "&"+"&TEXT($C$32,"#,##0")&" (Q2'25) to "&TEXT($D$32,"#,##0")&" (Q2'26). Interest expense rose to 1,278 from 261 on a debt book that grew from "&TEXT('04 Balance Sheet'!$D$17,"#,##0")&" (FY2024) to "&TEXT('04 Balance Sheet'!$G$17,"#,##0")&" (Jun'26), but interest income of 1,430 still exceeds it; most of the swing is the 'other' line (-973). Model it explicitly." -> • THE EX-GAIN LINE: other income excluding the securities gain went +1,376 (Q2'25) to -1,048 (Q2'26). Interest expense rose to 1,278 from 261 on a debt book that grew from 13,559 (FY2024) to 102,754 (Jun'26), but interest income of 1,430 still exceeds it; most of the swing is the 'other' line (-973). Model it explicitly.
B44: ="• Reported Q2 net income grew "&"+"&TEXT($E$36,"0.0")&"%"&" and reported EPS "&"+"&TEXT($E$37,"0.0")&"%"&". Core EPS grew "&"+"&TEXT($E$38,"0.0")&"%"&"." -> • Reported Q2 net income grew +297.9% and reported EPS +294.4%. Core EPS grew +23.8%.

Sheet 03 Segments
B2: 03 — SEGMENT REVENUE, OPERATING INCOME, GROWTH AND MARGIN
B3: $ millions.
B5: Revenue by segment
B6: Line item | C6: FY2023 | D6: FY2024 | E6: FY2025 | F6: Q1'25 | G6: Q1'26 | H6: Q2'25 | I6: Q2'26
B7: Google Search & other | C7: 175033 | D7: 198084 | E7: 224532 | F7: 50702 | G7: 60399 | H7: 54190 | I7: 63271
B8: YouTube ads | C8: 31510 | D8: 36147 | E8: 40367 | F8: 8927 | G8: 9883 | H8: 9796 | I8: 11055
B9: Google Network | C9: 31312 | D9: 30359 | E9: 29792 | F9: 7256 | G9: 6971 | H9: 7354 | I9: 7303
B10: Google advertising subtotal | C10: =C7+C8+C9 -> 237855 | D10: =D7+D8+D9 -> 264590 | E10: =E7+E8+E9 -> 294691 | F10: =F7+F8+F9 -> 66885 | G10: =G7+G8+G9 -> 77253 | H10: =H7+H8+H9 -> 71340 | I10: =I7+I8+I9 -> 81629
B11: Subscriptions, platforms & devices | C11: 34688 | D11: 40340 | E11: 48030 | F11: 10379 | G11: 12384 | H11: 11203 | I11: 12911
B12: GOOGLE SERVICES TOTAL | C12: =C10+C11 -> 272543 | D12: =D10+D11 -> 304930 | E12: =E10+E11 -> 342721 | F12: =F10+F11 -> 77264 | G12: =G10+G11 -> 89637 | H12: =H10+H11 -> 82543 | I12: =I10+I11 -> 94540
B13: Google Cloud | C13: 33088 | D13: 43229 | E13: 58705 | F13: 12260 | G13: 20028 | H13: 13624 | I13: 24768
B14: Other Bets | C14: 1527 | D14: 1648 | E14: 1537 | F14: 450 | G14: 411 | H14: 373 | I14: 382
B15: Hedging gains (losses) | C15: 236 | D15: 211 | E15: -127 | F15: 260 | G15: -180 | H15: -112 | I15: 106
B16: TOTAL REVENUES | C16: =C12+C13+C14+C15 -> 307394 | D16: =D12+D13+D14+D15 -> 350018 | E16: =E12+E13+E14+E15 -> 402836 | F16: =F12+F13+F14+F15 -> 90234 | G16: =G12+G13+G14+G15 -> 109896 | H16: =H12+H13+H14+H15 -> 96428 | I16: =I12+I13+I14+I15 -> 119796
B18: Operating income (loss) by segment
B19: Line item | C19: FY2023 | D19: FY2024 | E19: FY2025 | F19: Q1'25 | G19: Q1'26 | H19: Q2'25 | I19: Q2'26
B20: Google Services | C20: 95858 | D20: 121263 | E20: 139404 | F20: 32682 | G20: 40589 | H20: 33063 | I20: 39544
B21: Google Cloud | C21: 1716 | D21: 6112 | E21: 13910 | F21: 2177 | G21: 6598 | H21: 2826 | I21: 8814
B22: Other Bets | C22: -4095 | D22: -4444 | E22: -7515 | F22: -1226 | G22: -2100 | H22: -1246 | I22: -1799
B23: Alphabet-level activities | C23: -9186 | D23: -10541 | E23: -16760 | F23: -3027 | G23: -5391 | H23: -3372 | I23: -5789
B24: TOTAL INCOME FROM OPERATIONS | C24: =C20+C21+C22+C23 -> 84293 | D24: =D20+D21+D22+D23 -> 112390 | E24: =E20+E21+E22+E23 -> 129039 | F24: =F20+F21+F22+F23 -> 30606 | G24: =G20+G21+G22+G23 -> 39696 | H24: =H20+H21+H22+H23 -> 31271 | I24: =I20+I21+I22+I23 -> 40770
B26: Revenue growth, YoY %
B27: Line item | C27: FY2024 | D27: FY2025 | E27: Q1'26 | F27: Q2'26
B28: Search & other | C28: =(D7/C7-1)*100 -> 13.169517 | D28: =(E7/D7-1)*100 -> 13.351911 | E28: =(G7/F7-1)*100 -> 19.125478 | F28: =(I7/H7-1)*100 -> 16.757704
B29: YouTube ads | C29: =(D8/C8-1)*100 -> 14.715963 | D29: =(E8/D8-1)*100 -> 11.674551 | E29: =(G8/F8-1)*100 -> 10.709085 | F29: =(I8/H8-1)*100 -> 12.852185
B30: Google Network | C30: =(D9/C9-1)*100 -> -3.0435616 | D30: =(E9/D9-1)*100 -> -1.8676504 | E30: =(G9/F9-1)*100 -> -3.9277839 | F30: =(I9/H9-1)*100 -> -0.69350014
B31: Subscriptions/platforms/devices | C31: =(D11/C11-1)*100 -> 16.293819 | D31: =(E11/D11-1)*100 -> 19.062965 | E31: =(G11/F11-1)*100 -> 19.317853 | F31: =(I11/H11-1)*100 -> 15.245916
B32: Google Services | C32: =(D12/C12-1)*100 -> 11.883262 | D32: =(E12/D12-1)*100 -> 12.393336 | E32: =(G12/F12-1)*100 -> 16.013926 | F32: =(I12/H12-1)*100 -> 14.534243
B33: Google Cloud | C33: =(D13/C13-1)*100 -> 30.648574 | D33: =(E13/D13-1)*100 -> 35.800042 | E33: =(G13/F13-1)*100 -> 63.360522 | F33: =(I13/H13-1)*100 -> 81.796829
B34: Total | C34: =(D16/C16-1)*100 -> 13.866243 | D34: =(E16/D16-1)*100 -> 15.090081 | E34: =(G16/F16-1)*100 -> 21.790013 | F34: =(I16/H16-1)*100 -> 24.233625
B36: Segment operating margin %
B37: Line item | C37: FY2023 | D37: FY2024 | E37: FY2025 | F37: Q1'26 | G37: Q2'26
B38: Google Services operating margin % | C38: =C20/C12*100 -> 35.171698 | D38: =D20/D12*100 -> 39.767488 | E38: =E20/E12*100 -> 40.675652 | F38: =G20/G12*100 -> 45.281524 | G38: =I20/I12*100 -> 41.827798
B39: Google Cloud operating margin % | C39: =C21/C13*100 -> 5.1861702 | D39: =D21/D13*100 -> 14.138657 | E39: =E21/E13*100 -> 23.694745 | F39: =G21/G13*100 -> 32.943879 | G39: =I21/I13*100 -> 35.58624
B41: Notes and caveats
B42: • Hedging gains (losses) are filed figures: Alphabet reports them as their own line in the revenue-by-type table (Q2 2026 10-Q R39: 106 and (112); FY2025 10-K R44: (127), 211 and 236). Corrected 2026-10-16; this note had called the Q2 figures a derived residual.
B43: ="• Cloud margin arc is the standout: "&TEXT($C$39,"0.0")&"% -> "&TEXT($D$39,"0.0")&"% -> "&TEXT($E$39,"0.0")&"% -> "&TEXT($F$39,"0.0")&"% (Q1'26) -> "&TEXT($G$39,"0.0")&"% (Q2'26)"&", on revenue that grew "&"+"&TEXT($F$33,"0.0")&"% YoY"&"." -> • Cloud margin arc is the standout: 5.2% -> 14.1% -> 23.7% -> 32.9% (Q1'26) -> 35.6% (Q2'26), on revenue that grew +81.8% YoY.
B44: ="• Services margin of "&TEXT($G$38,"0.0")&"% in Q2 vs "&TEXT($F$38,"0.0")&"% in Q1"&": Q1 is seasonally stronger, so read the pair rather than the sequential step-down." -> • Services margin of 41.8% in Q2 vs 45.3% in Q1: Q1 is seasonally stronger, so read the pair rather than the sequential step-down.
B45: ="• Alphabet-level activities (shared AI/DeepMind R&D, unallocated) is the fast-growing cost offset: "&TEXT($H$23,"#,##0")&" (Q2'25) -> "&TEXT($G$23,"#,##0")&" (Q1'26) -> "&TEXT($I$23,"#,##0")&" (Q2'26), +"&TEXT(($I$23/$H$23-1)*100,"0.0")&"% YoY"&"." -> • Alphabet-level activities (shared AI/DeepMind R&D, unallocated) is the fast-growing cost offset: -3,372 (Q2'25) -> -5,391 (Q1'26) -> -5,789 (Q2'26), +71.7% YoY.
B46: ="• Cloud backlog / remaining performance obligations at Jun 30, 2026: "&TEXT('15 Assumptions'!$C$112,"#,##0")&" (Cloud) of 519,500 total RPO. Just over 50% expected to convert within 24 months."&" Model cross-check at 17 Model rows 107-112." -> • Cloud backlog / remaining performance obligations at Jun 30, 2026: 513,900 (Cloud) of 519,500 total RPO. Just over 50% expected to convert within 24 months. Model cross-check at 17 Model rows 107-112.

Sheet 04 Balance Sheet
B2: 04 — BALANCE SHEET
B3: $ millions. Balance-sheet figures are point-in-time. FY2023-FY2025 are at December 31; Mar'26 and Jun'26 are at quarter end. All periods complete as filed.
B5: Line item | C5: FY2023 | D5: FY2024 | E5: FY2025 | F5: Mar'26 | G5: Jun'26
B6: Cash & equivalents | C6: 24048 | D6: 23466 | E6: 30708 | F6: 38063 | G6: 55911
B7: Marketable securities | C7: 86868 | D7: 72191 | E7: 96135 | F7: 88777 | G7: 186563
B8: Cash + marketable securities | C8: =C6+C7 -> 110916 | D8: =D6+D7 -> 95657 | E8: =E6+E7 -> 126843 | F8: =F6+F7 -> 126840 | G8: =G6+G7 -> 242474
B9: Receivables | C9: 47964 | D9: 52340 | E9: 62886 | F9: 62999 | G9: 69175
B10: Total current assets | C10: 171530 | D10: 163711 | E10: 206038 | F10: 213753 | G10: 343524
B11: Property & equipment, net (as previously carried) | C11: 148436 | D11: 184624 | E11: 261818 | F11: 296529 | G11: 321212
B12: Property & equipment, net (AS FILED) | C12: 134345 | D12: 171036 | E12: 246597 | F12: 281020 | G12: 321212 | H12: Complete - all periods as filed
B13: Goodwill | C13: 29198 | D13: 31885 | E13: 33380 | F13: 57774 | G13: 57828
B14: Total assets | C14: 402392 | D14: 450256 | E14: 595281 | F14: 703919 | G14: 921983
B15: Total current liabilities | C15: 81814 | D15: 89122 | E15: 102745 | F15: 111188 | G15: 126111
B16: Long-term debt | C16: 11870 | D16: 10883 | E16: 46547 | F16: 77501 | G16: 98165
B17: Total debt (excl. operating leases) | C17: 14536 | D17: 13559 | E17: 51043 | F17: 81713 | G17: 102754 | H17: Filed: long-term debt + current portion + finance leases
B18: Total liabilities | C18: 119013 | D18: 125172 | E18: 180016 | F18: 225173 | G18: 281503
B19: Total stockholders' equity | C19: 283379 | D19: 325084 | E19: 415265 | F19: 478746 | G19: 640480
B20: Common shares outstanding | C20: 12433 | D20: 12190 | E20: 12097 | F20: 12116 | G20: 12230
B21: Memo: operating lease liabilities (not debt) | C21: 15251 | D21: 14578 | E21: 15954 | F21: 16161 | G21: 18037 | H21: Lease cost is already in operating expenses and FCFF
B22: Net cash (derived) | C22: =C8-C17 -> 96380 | D22: =D8-D17 -> 82098 | E22: =E8-E17 -> 75800 | F22: =F8-F17 -> 45127 | G22: =G8-G17 -> 139720 | H22: DERIVED = cash+securities less total debt
B24: Notes and caveats
B25: ="• PP&E IS CARRIED AS FILED. Net PP&E is "&TEXT($D$12,"#,##0")&" at Dec 31 2024 and "&TEXT($E$12,"#,##0")&" at Dec 31 2025, per the FY2025 10-K property note. Standardized data feeds commonly fold lease right-of-use assets into PP&E, which overstates the figure and by a gap that grows year over year - the "&"AS FILED row in this sheet avoids that." -> • PP&E IS CARRIED AS FILED. Net PP&E is 171,036 at Dec 31 2024 and 246,597 at Dec 31 2025, per the FY2025 10-K property note. Standardized data feeds commonly fold lease right-of-use assets into PP&E, which overstates the figure and by a gap that grows year over year - the AS FILED row in this sheet avoids that.
B26: ="• USE THE AS FILED ROW (row 12) for all PP&E work. It is complete for every period: "&TEXT($C$12,"#,##0")&" / "&TEXT($D$12,"#,##0")&" / "&TEXT($E$12,"#,##0")&" / "&TEXT($F$12,"#,##0")&" / "&TEXT($G$12,"#,##0")&". Row 11 is retained only to show the overstatement in the standardized feed and must not be used in the model." -> • USE THE AS FILED ROW (row 12) for all PP&E work. It is complete for every period: 134,345 / 171,036 / 246,597 / 281,020 / 321,212. Row 11 is retained only to show the overstatement in the standardized feed and must not be used in the model.
B27: • All Jun'26 lines are taken from the Q2 2026 10-Q.
B28: ="• Mar'26 is PRE the 2026 equity raise; Jun'26 is post-raise. Cash and securities nearly doubled to "&TEXT($G$8,"#,##0")&" and net cash rose to "&"+"&TEXT($G$22,"#,##0")&" from "&"+"&TEXT($F$22,"#,##0")&". Jun'26 figures are as filed. Total debt excludes operating lease liabilities (row 21), because their cost already sits in operating expenses and in free cash flow; counting them as debt too double-c"&"ounted them (corrected 2026-09-24, entry 44)." -> • Mar'26 is PRE the 2026 equity raise; Jun'26 is post-raise. Cash and securities nearly doubled to 242,474 and net cash rose to +139,720 from +45,127. Jun'26 figures are as filed. Total debt excludes operating lease liabilities (row 21), because their cost already sits in operating expenses and in free cash flow; counting them as debt too double-counted them (corrected 2026-09-24, entry 44).
B29: • Goodwill rose 33,380 -> 57,774 at Mar 2026, an increase of 24,394, as the Wiz and Intersect acquisitions closed in Q1 2026 (57,828 at Jun 2026). Corrected 2026-10-13: this note put the Wiz goodwill at about 33,000, which is close to the purchase price, not the goodwill.
B30: ="• Common shares outstanding at Jun'26 is the July 15, 2026 cover-page count "&"(Class A "&TEXT('05 Capital Structure'!$C$18,"#,##0")&" / Class B "&TEXT('05 Capital Structure'!$C$19,"#,##0")&" / Class C "&TEXT('05 Capital Structure'!$C$20,"#,##0")&")"&"." -> • Common shares outstanding at Jun'26 is the July 15, 2026 cover-page count (Class A 5,868 / Class B 835 / Class C 5,527).
B32: MEMO ADDED 2026-10-07: DEFERRED TAX AND EQUITY STAKES (Q2 2026 10-Q; 29 Change Log entries 53 and 58)
B33: Memo line | E33: FY2025 | G33: Jun'26 | H33: Basis
B34: Deferred income taxes, liability | E34: 919 | G34: 22819 | H34: filed, Q2 2026 10-Q balance sheet (R2)
B35: Deferred income taxes, asset | E35: 9113 | G35: 1448 | H35: filed, Q2 2026 10-Q balance sheet (R2)
B36: Net deferred tax liability | E36: =E34-E35 -> -8194 | G36: =G34-G35 -> 21371 | H36: DERIVED
B37: Increase in H1'26 as % of H1'26 equity-securities gains | G37: =(G36-E36)/'06 Core EPS Bridge'!J7 -> 0.21747606 | H37: DERIVED: corroborates a ~21% rate on the gains
B39: Equity stakes | E39: FY2025 | G39: Jun'26 | H39: Basis
B40: Marketable equity securities, inside marketable securities (row 7) | G40: 87063 | H40: filed, Q2 2026 10-Q financial instruments note (R12)
B41: Debt securities, inside marketable securities (government 51,822, corporate 26,157, MBS/ABS 21,521) | G41: 99500 | H41: filed, Q2 2026 10-Q financial instruments note (R12)
B42: Marketable equity securities in other non-current assets | G42: 14126 | H42: filed, R12; in the 20 DCF bridge at fair value since 2026-10-07
B43: Non-marketable securities (balance-sheet line) | E43: 68687 | G43: 131461 | H43: filed, Q2 2026 10-Q balance sheet (R2)
B44: of which non-marketable equity securities under the measurement alternative, carrying value | E44: 64094 | G44: 124259 | H44: filed, Q2 2026 10-Q financial instruments note (R12)
B45: initial cost | G45: 47642 | H45: filed, Q2 2026 10-Q financial instruments note (R12)
...

Sheet 05 Capital Structure
B2: 05 — CAPITAL STRUCTURE AFTER THE JUNE 2026 RAISE
B3: $ millions. Confirmed against the Q2 2026 10-Q.
B5: Component | C5: Amount | D5: Note
B6: Common stock offering (June 2026) | C6: 30500 | D6: net of costs
B7: 6.25% mandatory convertible preferred, Series A + B | C7: 19000 | D7: 19M shares, $1,000 liquidation preference, issued June 5, 2026
B8: ATM program drawn through June 30, 2026 (40,000 authorised) | C8: 0 | D8: none sold at June 30 per the Q2 10-Q
B9: TOTAL RAISED | C9: =C6+C7+C8 -> 49500 | D9: vs the $84,750 headline figure
B11: Share counts (millions)
B12: Measure | C12: Shares
B13: Q2 2026 weighted-average basic | C13: 12151
B14: Q2 2026 weighted-average diluted | C14: ='02 Quarterly'!D39 -> 12309
B15: H1 2026 weighted-average basic | C15: 12125
B16: H1 2026 weighted-average diluted | C16: 12274
B17: Shares outstanding, July 15, 2026 | C17: =C18+C19+C20 -> 12230
B18: of which Class A | C18: 5868
B19: of which Class B | C19: 835
B20: of which Class C | C20: 5527
B21: H1 2025 weighted-average diluted | C21: 12245 | D21: Filed, Q2 2025 10-Q. Used to roll TTM share count the same way as TTM EPS
B22: Model inputs
B23: Item | C23: Value | D23: Note
B24: Preferred dividend, annual | C24: =C7*0.0625 -> 1187.5 | D24: DERIVED = 19,000 x 6.25%
B25: Net cash at Jun'26 | C25: ='04 Balance Sheet'!G22 -> 139720 | D25: ="DERIVED = "&TEXT('04 Balance Sheet'!G8,"#,##0")&" less "&TEXT('04 Balance Sheet'!G17,"#,##0") -> DERIVED = 242,474 less 102,754
B26: Net cash at Mar'26 | C26: ='04 Balance Sheet'!F22 -> 45127 | D26: DERIVED - pre-raise; use the Jun'26 figure in row 25
B28: Notes and caveats
B29: ="• THE RAISE AS FILED: "&TEXT($C$6,"#,##0")&" of common"&" stock and "&TEXT($C$7,"#,##0")&" of preferred"&", "&"about "&TEXT($C$9,"#,##0")&" in total"&". The 40,000 ATM was authorised on June 1 2026 and no shares had been sold under it by June 30 (Q2 10-Q); it is forward dilution, stated to fund tax on employee equity grants. Corrected 2026-09-24 fro"&"m 'already drawn 30,400', which double-counted the common offering." -> • THE RAISE AS FILED: 30,500 of common stock and 19,000 of preferred, about 49,500 in total. The 40,000 ATM was authorised on June 1 2026 and no shares had been sold under it by June 30 (Q2 10-Q); it is forward dilution, stated to fund tax on employee equity grants. Corrected 2026-09-24 from 'already drawn 30,400', which double-counted the common offering.
B30: • SHARE COUNT: rows 13 to 16 and 21 are filed weighted averages (corrected to the Q2 10-Q 2026-09-24). The forecast count on 17 Model row 37 grows by stock-based compensation issued at the reference price.
B31: ="• PREFERRED is "&TEXT($C$7,"#,##0")&" at 6.25%"&", which is "&"roughly "&TEXT($C$24,"#,##0")&" PER YEAR"&" of preferred dividends reducing income available to common, plus dilution on mandatory conversion. Both effects must be carried in any per-share figure." -> • PREFERRED is 19,000 at 6.25%, which is roughly 1,188 PER YEAR of preferred dividends reducing income available to common, plus dilution on mandatory conversion. Both effects must be carried in any per-share figure.
B32: • THE EPS BUILD NEEDS A PREFERRED DIVIDEND LINE.
B33: • Buybacks remain suspended, so the historical share-count tailwind is gone and the count now drifts up.
B34: ="• Net cash at Jun'26 is "&"+"&TEXT($C$25,"#,##0")&" ("&TEXT('04 Balance Sheet'!$G$8,"#,##0")&" cash and securities less "&TEXT('04 Balance Sheet'!$G$17,"#,##0")&" of debt: "&TEXT('04 Balance Sheet'!$G$16,"#,##0")&" long-term, 1,999 current and 2,590 finance leases), up from "&"+"&TEXT($C$26,"#,##0")&" at Mar'26. Operating lease liabilities of "&TEXT('04 Balance Sheet'!$G$21,"#,##0")&" are not debt here because FCFF already pays the lease cost. Use the Jun'26 figure in the DCF equity bridge." -> • Net cash at Jun'26 is +139,720 (242,474 cash and securities less 102,754 of debt: 98,165 long-term, 1,999 current and 2,590 finance leases), up from +45,127 at Mar'26. Operating lease liabilities of 18,037 are not debt here because FCFF already pays the lease cost. Use the Jun'26 figure in the DCF equity bridge.
B35: ="• Other income excluding the securities gain went "&"+"&TEXT('02 Quarterly'!$C$32,"#,##0")&" (Q2'25) to "&TEXT('02 Quarterly'!$D$32,"#,##0")&" (Q2'26). Interest expense rose to 1,278 from 261 on a debt book that grew from "&TEXT('04 Balance Sheet'!$D$17,"#,##0")&" (FY2024) to "&TEXT('04 Balance Sheet'!$G$17,"#,##0")&" (Jun'26), but interest income of 1,430 still exceeds it; most of the swing is the 'other' line (-973). Model it explicitly." -> • Other income excluding the securities gain went +1,376 (Q2'25) to -1,048 (Q2'26). Interest expense rose to 1,278 from 261 on a debt book that grew from 13,559 (FY2024) to 102,754 (Jun'26), but interest income of 1,430 still exceeds it; most of the swing is the 'other' line (-973). Model it explicitly.
B36: ="• DISCLOSURE NOTE: two consecutive earnings calls (Apr 29 and Jul 22) passed with NO mention of the equity raise, buybacks, or the preferred. "&"The "&TEXT($C$9,"#,##0")&" raise (common plus preferred, as filed)"&" priced five weeks after the April call without being signalled on it." -> • DISCLOSURE NOTE: two consecutive earnings calls (Apr 29 and Jul 22) passed with NO mention of the equity raise, buybacks, or the preferred. The 49,500 raise (common plus preferred, as filed) priced five weeks after the April call without being signalled on it.

Sheet 06 Core EPS Bridge
B2: 06 — NORMALIZED (CORE) EPS BRIDGE
B3: Strip the gain on equity securities, tax the gain at the gains rate ('15 Assumptions' C85), treat the rest of reported tax as core tax, divide by diluted shares.
B5: Line item | C5: FY2023 | D5: FY2024 | E5: FY2025 | F5: Q1'25 | G5: Q1'26 | H5: Q2'25 | I5: Q2'26 | J5: H1'26 | K5: Basis
B6: Reported pretax income | C6: 85717 | D6: 119815 | E6: 158826 | F6: 41789 | G6: 77412 | H6: 33933 | I6: 138753 | J6: =G6+I6 -> 216165 | K6: filed
B7: less: gain on equity securities | C7: 392 | D7: 3714 | E7: 24080 | F7: 9758 | G7: 36915 | H7: 1286 | I7: 99031 | J7: =G7+I7 -> 135946 | K7: filed
B8: Normalized pretax income | C8: =C6-C7 -> 85325 | D8: =D6-D7 -> 116101 | E8: =E6-E7 -> 134746 | F8: =F6-F7 -> 32031 | G8: =G6-G7 -> 40497 | H8: =H6-H7 -> 32647 | I8: =I6-I7 -> 39722 | J8: =J6-J7 -> 80219 | K8: DERIVED
B9: Core effective tax rate applied % (row 36) | C9: =C36 -> 13.87598 | D9: =D36 -> 16.293624 | E9: =E36 -> 16.029567 | F9: =F36 -> 16.233711 | G9: =G36 -> 17.487345 | H9: =H36 -> 16.745612 | I9: =I36 -> 14.509566 | J9: =J36 -> 16.01284 | K9: DERIVED
B10: Normalized net income | C10: =C8-C35 -> 73485.32 | D10: =D8-D35 -> 97183.94 | E10: =E8-E35 -> 113146.8 | F10: =F8-F35 -> 26831.18 | G10: =G8-G35 -> 33415.15 | H10: =H8-H35 -> 27180.06 | I10: =I8-I35 -> 33958.51 | J10: =J8-J35 -> 67373.66 | K10: DERIVED
B11: Diluted shares | C11: 12722 | D11: 12447 | E11: 12230 | F11: 12291 | G11: 12238 | H11: 12198 | I11: ='02 Quarterly'!D39 -> 12309 | J11: ='05 Capital Structure'!C16 -> 12274 | K11: filed
B12: CORE diluted EPS ($) | C12: =C10/C11 -> 5.7762396 | D12: =D10/D11 -> 7.8078204 | E12: =E10/E11 -> 9.2515781 | F12: =F10/F11 -> 2.1829941 | G12: =G10/G11 -> 2.7304421 | H12: =H10/H11 -> 2.2282391 | I12: =I10/I11 -> 2.7588358 | J12: =J10/J11 -> 5.4891364 | K12: DERIVED
B13: Reported diluted EPS ($) | C13: 5.8 | D13: 8.04 | E13: 10.81 | F13: 2.81 | G13: 5.11 | H13: 2.31 | I13: 9.11 | J13: 14.24 | K13: filed
B15: Derived summary figures
B16: Metric | C16: Reported | D16: CORE | E16: Basis
B17: TTM (Jun'26) EPS ($) | C17: ='01 Income Statement'!G19 -> 19.93 | D17: =E12-F12-H12+J12 -> 10.329481 | E17: DERIVED core
B18: FY2026E EPS ($) | C18: ='07 Consensus'!C6 -> 20.6 | D18: ='17 Model'!L48 -> 11.818616 | E18: consensus vs model core ('17 Model' L48, follows the scenario switch)
B19: ="P/E at $"&TEXT('11 Valuation'!$C$6,"0.00") -> P/E at $340.59 | C19: ='11 Valuation'!C6/C17 -> 17.089313 | D19: ='11 Valuation'!C6/D17 -> 32.972614 | E19: DERIVED core multiple
B20: ="Forward P/E at $"&TEXT('11 Valuation'!$C$6,"0.00") -> Forward P/E at $340.59 | C20: ='11 Valuation'!C6/C18 -> 16.533495 | D20: ='11 Valuation'!C6/D18 -> 28.818094 | E20: DERIVED core multiple
B22: Notes and caveats
B23: • Method (rebuilt 2026-10-07, entry 53): strip the gain on equity securities from pretax income; core tax is reported tax less the gain taxed at '15 Assumptions' C85 (rows 31-38). Before this, the blended period rate was applied to normalized income, which overstated core tax because the gains carry the higher rate.
B24: ="• Q2 2026 gain of "&TEXT($I$7,"#,##0")&" is the largest on record: "&TEXT($I$7/$G$7,"0.0")&"x"&" the prior record set one quarter earlier "&"("&TEXT($G$7,"#,##0")&")"&", "&TEXT($I$7/$E$7,"0.0")&"x"&" all of FY2025 "&"("&TEXT($E$7,"#,##0")&")"&", and "&TEXT($I$7/$I$6,"0%")&" of Q2"&" pretax income." -> • Q2 2026 gain of 99,031 is the largest on record: 2.7x the prior record set one quarter earlier (36,915), 4.1x all of FY2025 (24,080), and 71% of Q2 pretax income.
B25: ="• Reported Q2 2026 EPS grew "&"+"&TEXT(($I$13/$H$13-1)*100,"0")&"% YoY"&". CORE EPS grew "&"+"&TEXT(($I$12/$H$12-1)*100,"0.0")&"% ($"&TEXT($H$12,"0.00")&" -> $"&TEXT($I$12,"0.00")&")"&". The headline is an artifact." -> • Reported Q2 2026 EPS grew +294% YoY. CORE EPS grew +23.8% ($2.23 -> $2.76). The headline is an artifact.
B26: ="• Core H1 2026 EPS of "&TEXT(J12,"0.00")&" is "&TEXT(J12/J13,"0%")&" of the reported "&TEXT(J13,"0.00")&"." -> • Core H1 2026 EPS of 5.49 is 39% of the reported 14.24.
B27: ="• TTM (Jun'26) core EPS "&TEXT(D17,"0.00")&" vs reported "&TEXT(C17,"0.00")&". Built as FY2025 core "&TEXT(E12,"0.00")&" less H1'25 core "&TEXT(F12+H12,"0.00")&" plus H1'26 core "&TEXT(J12,"0.00")&". Gains are the filed figures (XBRL EquitySecuritiesFvNiGainLoss), corrected 2026-09-24." -> • TTM (Jun'26) core EPS 10.33 vs reported 19.93. Built as FY2025 core 9.25 less H1'25 core 4.41 plus H1'26 core 5.49. Gains are the filed figures (XBRL EquitySecuritiesFvNiGainLoss), corrected 2026-09-24.
B28: ="• FY2026E core EPS is "&TEXT('06 Core EPS Bridge'!$D$18,"0.00")&" ("&'16 Scenarios'!$F$6&"), linked live to '17 Model' L48 since 2026-09-21. It replaced a hard-typed ~10.85 (H1 actual core 5.29 plus an assumed H2 path), which predated the model." -> • FY2026E core EPS is 11.82 (BASE CASE), linked live to '17 Model' L48 since 2026-09-21. It replaced a hard-typed ~10.85 (H1 actual core 5.29 plus an assumed H2 path), which predated the model.
B29: • ALL rows marked DERIVED are my own arithmetic, not filed figures. Re-check before publication.
B31: CORE TAX REBUILT 2026-10-07: reported tax less the tax on the equity-securities gain (29 Change Log entry 53)
B32: Line item | C32: =C$5 -> FY2023 | D32: =D$5 -> FY2024 | E32: =E$5 -> FY2025 | F32: =F$5 -> Q1'25 | G32: =G$5 -> Q1'26 | H32: =H$5 -> Q2'25 | I32: =I$5 -> Q2'26 | J32: =J$5 -> H1'26 | K32: Basis
B33: Reported provision for income taxes | C33: ='01 Income Statement'!C16 -> 11922 | D33: ='01 Income Statement'!D16 -> 19697 | E33: ='01 Income Statement'!E16 -> 26656 | F33: ='02 Quarterly'!C15 -> 7249 | G33: ='02 Quarterly'!D15 -> 14834 | H33: ='02 Quarterly'!C34 -> 5737 | I33: ='02 Quarterly'!D34 -> 26560 | J33: =G33+I33 -> 41394 | K33: filed
B34: less: tax on the equity-securities gain (row 7 x '15 Assumptions' C85) | C34: =C7*'15 Assumptions'!$C$85 -> 82.32 | D34: =D7*'15 Assumptions'!$C$85 -> 779.94 | E34: =E7*'15 Assumptions'!$C$85 -> 5056.8 | F34: =F7*'15 Assumptions'!$C$85 -> 2049.18 | G34: =G7*'15 Assumptions'!$C$85 -> 7752.15 | H34: =H7*'15 Assumptions'!$C$85 -> 270.06 | I34: =I7*'15 Assumptions'!$C$85 -> 20796.51 | J34: =J7*'15 Assumptions'!$C$85 -> 28548.66 | K34: DERIVED
B35: Core tax | C35: =C33-C34 -> 11839.68 | D35: =D33-D34 -> 18917.06 | E35: =E33-E34 -> 21599.2 | F35: =F33-F34 -> 5199.82 | G35: =G33-G34 -> 7081.85 | H35: =H33-H34 -> 5466.94 | I35: =I33-I34 -> 5763.49 | J35: =J33-J34 -> 12845.34 | K35: DERIVED
B36: Core effective tax rate % | C36: =C35/C8*100 -> 13.87598 | D36: =D35/D8*100 -> 16.293624 | E36: =E35/E8*100 -> 16.029567 | F36: =F35/F8*100 -> 16.233711 | G36: =G35/G8*100 -> 17.487345 | H36: =H35/H8*100 -> 16.745612 | I36: =I35/I8*100 -> 14.509566 | J36: =J35/J8*100 -> 16.01284 | K36: DERIVED
B37: Reported effective tax rate %, for reference | C37: =C33/C6*100 -> 13.90856 | D37: =D33/D6*100 -> 16.439511 | E37: =E33/E6*100 -> 16.783146 | F37: =F33/F6*100 -> 17.34667 | G37: =G33/G6*100 -> 19.162404 | H37: =H33/H6*100 -> 16.906846 | I37: =I33/I6*100 -> 19.141928 | J37: =J33/J6*100 -> 19.149261 | K37: filed-derived
B38: Check: core tax + gain tax - reported tax (must be 0) | C38: =C35+C34-C33 -> 0 | D38: =D35+D34-D33 -> 0 | E38: =E35+E34-E33 -> 0 | F38: =F35+F34-F33 -> 0 | G38: =G35+G34-G33 -> 0 | H38: =H35+H34-H33 -> 0 | I38: =I35+I34-I33 -> 0 | J38: =J35+J34-J33 -> 0 | K38: check

Sheet 07 Consensus
B2: 07 — CONSENSUS ESTIMATES AND THE IMPLIED NET MARGIN
B3: Rows 6-32: FY2026 GAAP-basis consensus as of September 8, 2026, kept as a dated record. Rows 34-39 and 56-76: October 12-13, 2026 (StockAnalysis, MarketScreener). Rows 78-83: a provider check on October 16, 2026. $ millions except per-share.
B5: Metric | C5: Value | D5: Basis
B6: Consensus FY2026 EPS ($) | C6: 20.6 | D6: 51 analysts
B7: Consensus FY2026 revenue | C7: 498080
B8: Implied FY2026 net income | C8: ='07 Consensus'!C6*'05 Capital Structure'!C16 -> 252844.4 | D8: ="DERIVED = consensus EPS x H1'26 wtd-avg DILUTED shares ("&TEXT('05 Capital Structure'!$C$16,"#,##0")&")" -> DERIVED = consensus EPS x H1'26 wtd-avg DILUTED shares (12,274)
B9: IMPLIED NET MARGIN % | C9: =C8/C7*100 -> 50.763813
B11: Alphabet Q2 2026 operating margin % | C11: ='02 Quarterly'!D29 -> 34.032856 | D11: actual
B12: Alphabet FY2025 net margin % | C12: ='01 Income Statement'!E18/'01 Income Statement'!E6*100 -> 32.809878 | D12: ="actual, already includes "&TEXT('06 Core EPS Bridge'!$E$7,"#,##0")&" of gains" -> actual, already includes 24,080 of gains
B13: Alphabet FY2025 CORE net margin % | C13: ='06 Core EPS Bridge'!E10/'01 Income Statement'!E6*100 -> 28.087559
B15: Average price target ($) | C15: 430.4 | D15: ="+"&TEXT(C15/'11 Valuation'!$C$6-1,"0.0%")&" vs "&TEXT('11 Valuation'!$C$6,"$0.00") -> +26.4% vs $340.59
B16: Median price target ($) | C16: 430
B17: High price target ($) | C17: 515
B18: Low price target ($) | C18: 340
B20: Ratings - Strong Buy | C20: 44
B21: Ratings - Buy | C21: 13
B22: Ratings - Hold | C22: 5
B23: Ratings - Sell | C23: 0
B24: Ratings - Strong Sell | C24: 0
B26: FY2026 EPS - LOW estimate ($) | C26: 19.7 | D26: most bearish of 51 analysts
B27: FY2026 EPS - mean ($) | C27: =C6 -> 20.6
B28: FY2026 EPS - HIGH estimate ($) | C28: 21.92
B29: FY2026 EPS spread as % of mean | C29: =(C28-C26)/C27*100 -> 10.776699 | D29: DERIVED
B30: FY2026 revenue - LOW | C30: 489800
B31: FY2026 revenue - HIGH | C31: 519800
B32: FY2026 revenue spread as % of mean | C32: =(C31-C30)/C7*100 -> 6.0231288 | D32: DERIVED
B34: FY2027 EPS - consensus mean ($) | C34: 15.24 | D34: StockAnalysis, Oct 12 2026 (S&P Global poll). The page gave +28.95% on its FY2026 mean of 11.82 (row 67), a provider-stated growth rate. Was 14.84 on Sep 8 (49 analysts, range 13.67-17.21); the range is not shown on the free page. 15.25 on Oct 16 (row 80).
B35: FY2027 revenue - consensus | C35: 618790 | D35: StockAnalysis, Oct 12 2026. Was 612,190 in Sep.
B36: FY2026 EBIT - consensus | C36: 171690 | D36: MarketScreener, retrieved Oct 13 2026; on revenue 499,293. Was 171,734 on Sep 21.
B37: FY2026 operating margin - consensus % | C37: 34.39 | D37: MarketScreener, provider-stated, Oct 13 2026
B38: FY2027 EBIT - consensus | C38: 218330 | D38: MarketScreener, retrieved Oct 13 2026; on revenue 618,791 and GAAP EPS 15.03. Was 216,725 on Sep 21.
B39: FY2027 operating margin - consensus % | C39: 35.28 | D39: MarketScreener, provider-stated, Oct 13 2026. EBT of 227,265 implies about 8,900 of pretax non-operating income.
B41: Notes and caveats
B42: ="• THE IMPLIED MARGIN, READ CORRECTLY: FY2026 consensus EPS of "&TEXT($C$6,"0.00")&" on consensus revenue of "&TEXT($C$7,"#,##0")&" implies a "&TEXT($C$9,"0.0")&"% NET margin against a "&TEXT($C$11,"0.0")&"% Q2 OPERATING margin. The gap is the H1'26 marks, which a GAAP-basis consensus has to include because they are booked: taking them out leaves about "&TEXT($C$63,"0.00")&" (row 63, derived here, not a published figure) against the model's core "&TEXT('06 Core EPS Bridge'!$D$18,"0.00")&", and FY2027 consensus of "&TEXT($C$34,"0.00")&" sits "&TEXT(1-$C$34/$C$6,"0%")&" below 20.60, consistent with marks that do not recur. Consensus is not mis-specified. The reported "&TEXT('11 Valuation'!$C$13,"0.0")&"x forward P/E on the September GAAP consensus makes the stock look cheaper than it is to anyone striking a multiple off GAAP EPS. The provider's own forward P/E ("&TEXT($C$70,"0.0")&"x, row 70) does not state its earnings basis, and by October 16 its FY2026 estimates mixed analysts who include the marks with analysts who leave them out (row 79). On the Q2 call nobody asked about the "&TEXT('06 Core EPS Bridge'!$I$7,"#,##0")&" gain." -> • THE IMPLIED MARGIN, READ CORRECTLY: FY2026 consensus EPS of 20.60 on consensus revenue of 498,080 implies a 50.8% NET margin against a 34.0% Q2 OPERATING margin. The gap is the H1'26 marks, which a GAAP-basis consensus has to include because they are booked: taking them out leaves about 11.85 (row 63, derived here, not a published figure) against the model's core 11.82, and FY2027 consensus of 15.24 sits 26% below 20.60, consistent with marks that do not recur. Consensus is not mis-specified. The reported 16.5x forward P/E on the September GAAP consensus makes the stock look cheaper than it is to anyone striking a multiple off GAAP EPS. The provider's own forward P/E (25.6x, row 70) does not state its earnings basis, and by October 16 its FY2026 estimates mixed analysts who include the marks with analysts who leave them out (row 79). On the Q2 call nobody asked about the 99,031 gain.
B43: ="• Consensus FY2026 EPS moved from 14.22 before the Q2 print to 20.60 after it. The rise of 6.38 is close to the Q2 gain of "&TEXT('06 Core EPS Bridge'!$I$7,"#,##0")&" after tax ("&TEXT('06 Core EPS Bridge'!$I$7*(1-'15 Assumptions'!$C$85)/'05 Capital Structure'!$C$16,"0.00")&" a share), so the marks explain most of it."&" This pack has no bridge of individual revisions, so changes to the operating outlook cannot be ruled out." -> • Consensus FY2026 EPS moved from 14.22 before the Q2 print to 20.60 after it. The rise of 6.38 is close to the Q2 gain of 99,031 after tax (6.37 a share), so the marks explain most of it. This pack has no bridge of individual revisions, so changes to the operating outlook cannot be ruled out.
B44: • REVISION DATA CORRECTION: verified 30-day revisions were FY2026 4 up / 1 down and FY2027 9 up / 1 down. An earlier secondary-source count was removed.
B45: • PRICE TARGETS: MarketBeat showed 420.19 across 54 analysts (range 255-515) in September against StockAnalysis's 428.07, so the 360.92 figure flagged earlier was the outlier and is not used. The current StockAnalysis mean is at C15.
B46: • FIRST NAMED POST-Q2 SELL-SIDE ACTIONS: BMO Capital 455 to 465 (raised), Barclays 405 to 425 (raised), PIPER SANDLER 445 to 395 (CUT). Piper's is the first target cut recorded since HSBC's before the Q2 print, and it comes from a house that had been raising into the earlier selloff.
B47: • DISPERSION INTERPRETATION: narrowing reflects booked H1 marks that analysts must include; it is not evidence that consensus is mis-specified.
B48: ="• THE MOST BEARISH ANALYST OF 51 IS AT "&TEXT($C$26,"0.00")&", against a core FY2026E of "&TEXT('06 Core EPS Bridge'!$D$18,"0.00")&" (17 Model). The panel works off the GAAP line, which includes the H1 marks already booked; excluding them, consensus is about "&TEXT($C$63,"0.00")&" (row 63; see 29 Change Log entry 31)." -> • THE MOST BEARISH ANALYST OF 51 IS AT 19.70, against a core FY2026E of 11.82 (17 Model). The panel works off the GAAP line, which includes the H1 marks already booked; excluding them, consensus is about 11.85 (row 63; see 29 Change Log entry 31).
...

Sheet 08 PPE and Depreciation
B2: 08 — PROPERTY & EQUIPMENT AND DEPRECIATION BASE
B3: $ millions. Policy from FY2025 10-K R31; asset detail from Q2 2026 10-Q R64.
B5: Asset class | C5: Dec 31, 2024 | D5: Dec 31, 2025 | E5: Jun 30, 2026 | F5: Change H1'26
B6: Technical infrastructure | C6: 141852 | D6: 203679 | E6: 247177 | F6: =E6-D6 -> 43498
B7: Office space | C7: 45403 | D7: 48348 | E7: 50635 | F7: =E7-D7 -> 2287
B8: Corporate and other assets | C8: 12574 | D8: 14463 | E8: 6498 | F8: =E8-D8 -> -7965
B9: ASSETS NOT YET IN SERVICE | C9: 50597 | D9: 78592 | E9: 122814 | F9: =E9-D9 -> 44222
B10: TOTAL GROSS PP&E | C10: =C6+C7+C8+C9 -> 250426 | D10: =D6+D7+D8+D9 -> 345082 | E10: =E6+E7+E8+E9 -> 427124 | F10: =E10-D10 -> 82042
B11: Less: accumulated depreciation | C11: -79390 | D11: -98485 | E11: -105912 | F11: =E11-D11 -> -7427
B12: NET PP&E | C12: =C10+C11 -> 171036 | D12: =D10+D11 -> 246597 | E12: =E10+E11 -> 321212 | F12: =E12-D12 -> 74615
B14: Estimated useful lives (unchanged; no change in accounting estimate disclosed)
B15: Asset class | C15: Estimated useful life
B16: Servers and network equipment | C16: generally 6 years
B17: Data center and office buildings | C17: 7 to 40 years
B18: Corporate and other assets | C18: 2 to 25 years
B19: Leasehold improvements | C19: shorter of remaining lease term or useful life
B20: Land | C20: not depreciated
B22: Depreciation ramp - illustrative only
B23: Metric | C23: Value | D23: Basis
B24: Assets not yet in service, Jun'26 | C24: =E9 -> 122814 | D24: filed
B25: As % of gross PP&E | C25: =C24/E10*100 -> 28.753711 | D25: DERIVED
B26: If placed in service on a 6-yr life: annual charge | C26: =C24/6 -> 20469 | D26: DERIVED - UPPER BOUND, see notes
B27: Current depreciation run rate, annualized | C27: ='09 Cash Flow'!G22*2 -> 27172 | D27: ="DERIVED = H1 "&TEXT('09 Cash Flow'!$G$22,"#,##0")&" x 2" -> DERIVED = H1 13,586 x 2
B28: Implied increase % | C28: =C26/C27*100 -> 75.331223 | D28: DERIVED - before any H2'26 or 2027 capex
B29: Implied H1 retirements / disposals | C29: ='09 Cash Flow'!G22+F11 -> 6159 | D29: ="DERIVED = "&TEXT('09 Cash Flow'!$G$22,"#,##0")&" expense less "&TEXT(-$F$11,"#,##0")&" accum-dep increase" -> DERIVED = 13,586 expense less 7,427 accum-dep increase
B31: Notes and caveats
B32: • POLICY, verbatim: "Property and equipment are stated at cost less accumulated depreciation. Depreciation commences once assets are ready for their intended use and is recorded using the straight-line method over the estimated useful lives of the assets, which we regularly evaluate for factors such as technological obsolescence and our planned use and utilization."
B33: • NO change in accounting estimate is disclosed in either the FY2025 10-K or the Q2 2026 10-Q. The 6-year server life set in the January 2023 revision (from 4 years) still stands.
B34: • TAIL RISK: the 'regularly evaluate ... technological obsolescence' language means a future shortening of the AI-vintage life would hit the P&L immediately.
B35: ="• KEY NUMBER: "&TEXT($C$24,"#,##0")&" sits in assets NOT YET IN SERVICE and is earning no depreciation. That is "&TEXT($C$25,"0.0")&"%"&" of gross PP&E, and it grew "&TEXT($F$9,"#,##0")&" in six months." -> • KEY NUMBER: 122,814 sits in assets NOT YET IN SERVICE and is earning no depreciation. That is 28.8% of gross PP&E, and it grew 44,222 in six months.
B36: ="• ILLUSTRATIVE RAMP: if that "&TEXT($C$24,"#,##0")&" were placed in service on the 6-year server life it alone would add "&"~"&TEXT($C$26,"#,##0")&"/yr"&", against a current run rate of "&"~"&TEXT($C$27,"#,##0")&" annualized (H1 "&TEXT('09 Cash Flow'!$G$22,"#,##0")&" doubled)"&". "&"A ~"&TEXT($C$28,"0")&"%"&" increase BEFORE any H2 2026 or 2027 capex. This is an UPPER BOUND on that tranche: the balance mixes 6-year servers with 7-40 year buildings, and the split is NOT disclosed." -> • ILLUSTRATIVE RAMP: if that 122,814 were placed in service on the 6-year server life it alone would add ~20,469/yr, against a current run rate of ~27,172 annualized (H1 13,586 doubled). A ~75% increase BEFORE any H2 2026 or 2027 capex. This is an UPPER BOUND on that tranche: the balance mixes 6-year servers with 7-40 year buildings, and the split is NOT disclosed.
B37: • THE SPLIT OF ASSETS-NOT-YET-IN-SERVICE BETWEEN SHORT- AND LONG-LIVED CLASSES IS THE SINGLE MOST SENSITIVE ASSUMPTION IN THE MODEL. Scenario it rather than picking a point estimate.
B38: ="• RETIREMENTS ARE MATERIAL: accumulated depreciation rose only "&TEXT(-$F$11,"#,##0")&" in H1 while depreciation expense was "&TEXT('09 Cash Flow'!$G$22,"#,##0")&", implying "&"~"&TEXT($C$29,"#,##0")&" of retirements and disposals. A roll-forward ignoring disposals will not tie." -> • RETIREMENTS ARE MATERIAL: accumulated depreciation rose only 7,427 in H1 while depreciation expense was 13,586, implying ~6,159 of retirements and disposals. A roll-forward ignoring disposals will not tie.
B39: ="• Corporate and other assets fell "&TEXT($D$8,"#,##0")&" -> "&TEXT($E$8,"#,##0")&", a "&TEXT(-$F$8/$D$8,"0%")&" drop"&" in six months. That is a reclassification or large disposal, not ordinary depreciation. Check the footnote; it may explain part of the retirement figure." -> • Corporate and other assets fell 14,463 -> 6,498, a 55% drop in six months. That is a reclassification or large disposal, not ordinary depreciation. Check the footnote; it may explain part of the retirement figure.
B40: ="• THE BUILD IS RECENT AND STEEP: technical infrastructure went "&TEXT($C$6,"#,##0")&" (Dec'24) to "&TEXT($D$6,"#,##0")&" (Dec'25) to "&TEXT($E$6,"#,##0")&" (Jun'26), +"&TEXT($E$6/$C$6-1,"0%")&" in eighteen months. Assets not yet in service went "&TEXT($C$9,"#,##0")&" to "&TEXT($D$9,"#,##0")&" to "&TEXT($E$9,"#,##0")&" over the same span, +"&TEXT($E$9/$C$9-1,"0%")&". The in-service base has not yet absorbed most of what has been bought." -> • THE BUILD IS RECENT AND STEEP: technical infrastructure went 141,852 (Dec'24) to 203,679 (Dec'25) to 247,177 (Jun'26), +74% in eighteen months. Assets not yet in service went 50,597 to 78,592 to 122,814 over the same span, +143%. The in-service base has not yet absorbed most of what has been bought.
B41: • Dec 2024 and Dec 2025 columns are from the FY2025 10-K note (R70); Jun 2026 from the Q2 10-Q (R64). The Dec 2025 gross total is 345,082 - the four classes sum to that and it ties to net PP&E after accumulated depreciation. An earlier reading recorded 345,182; that was a transcription error, corrected here.
B42: • Technical infrastructure is 247,177 gross, ~58% of the total. Blended against ~27,000 of current annual depreciation, the implied average life across the in-service base is well above 6 years, confirming buildings carry a meaningful share.
B43: • Recently issued standards not yet adopted, none affecting depreciation: ASU 2024-03 (expense disaggregation, 2027), ASU 2025-06 (internal-use software, 2028), ASU 2026-02 (environmental credits, 2028). ASU 2025-06 is worth tracking for software capitalization.

Sheet 09 Cash Flow
B2: 09 — CASH FLOW AND FREE CASH FLOW
B3: $ millions.
B5: Line item | C5: FY2023 | D5: FY2024 | E5: FY2025 | F5: TTM Mar'26 | G5: TTM Jun'26
B6: Net income | C6: ='01 Income Statement'!C18 -> 73795 | D6: ='01 Income Statement'!D18 -> 100118 | E6: ='01 Income Statement'!E18 -> 132170 | F6: ='01 Income Statement'!F18 -> 160208 | G6: ='01 Income Statement'!G18 -> 244205
B7: Depreciation & amortization | C7: 11946 | D7: 15311 | E7: 21136 | F7: 23131 | G7: =E7+G22-F22 -> 25237
B8: Stock-based compensation | C8: 22460 | D8: 22785 | E8: 24953 | F8: 26188 | G8: =E8+G23-F23 -> 28147
B9: Operating cash flow | C9: 101746 | D9: 125299 | E9: 164713 | F9: 174353 | G9: =E9+G19-F19 -> 185675
B10: Capital expenditures | C10: -32251 | D10: -52535 | E10: -91447 | F10: -109924 | G10: =E10+G20-F20 -> -132402
B11: FREE CASH FLOW | C11: =C9+C10 -> 69495 | D11: =D9+D10 -> 72764 | E11: =E9+E10 -> 73266 | F11: =F9+F10 -> 64429 | G11: =G9+G10 -> 53273
B12: FCF margin % | C12: =C11/'01 Income Statement'!C6*100 -> 22.607793 | D12: =D11/'01 Income Statement'!D6*100 -> 20.788645 | E12: =E11/'01 Income Statement'!E6*100 -> 18.18755 | F12: =F11/'01 Income Statement'!F6*100 -> 15.24954 | G12: =G11/'01 Income Statement'!G6*100 -> 11.948209
B13: Stock repurchases | C13: -61504 | D13: -62222 | E13: -45709 | F13: -30641
B14: Dividends paid | D14: -7363 | E14: -10049 | F14: -10157
B15: Acquisitions | C15: -495 | D15: -2931 | E15: -1592 | F15: -34873
B17: Quarterly detail around the inflection
B18: Line item | C18: Q2'25 | D18: Q1'26 | E18: Q2'26 | F18: H1'25 | G18: H1'26
B19: Operating cash flow | C19: 27747 | D19: =G19-E19 -> 45790 | E19: 39069 | F19: 63897 | G19: 84859
B20: Capital expenditures | C20: -22446 | D20: =G20-E20 -> -35674 | E20: -44924 | F20: -39643 | G20: -80598
B21: FREE CASH FLOW | C21: =C19+C20 -> 5301 | D21: =D19+D20 -> 10116 | E21: =E19+E20 -> -5855 | F21: =F19+F20 -> 24254 | G21: =G19+G20 -> 4261
B22: Depreciation | C22: 4998 | D22: =G22-E22 -> 6482 | E22: 7104 | F22: 9485 | G22: 13586
B23: Stock-based compensation | F23: 11514 | G23: 14708
B25: Notes and caveats
B26: ="• Q2 2026 is the FIRST NEGATIVE free-cash-flow quarter on record "&"("&TEXT($E$21,"#,##0")&")"&". H1'26 FCF of "&TEXT($G$21,"#,##0")&" is "&"down "&TEXT(1-$G$21/$F$21,"0%")&" from H1'25." -> • Q2 2026 is the FIRST NEGATIVE free-cash-flow quarter on record (-5,855). H1'26 FCF of 4,261 is down 82% from H1'25.
B27: ="• FCF trajectory: "&TEXT($C$11,"#,##0")&" -> "&TEXT($D$11,"#,##0")&" -> "&TEXT($E$11,"#,##0")&" -> "&TEXT($F$11,"#,##0")&" -> "&TEXT($G$11,"#,##0")&". FCF margin fell from "&TEXT($C$12,"0.0")&"% (FY2023) to "&TEXT($G$12,"0.0")&"%"&" (TTM Jun'26)." -> • FCF trajectory: 69,495 -> 72,764 -> 73,266 -> 64,429 -> 53,273. FCF margin fell from 22.6% (FY2023) to 11.9% (TTM Jun'26).
B28: • Q1'26 OCF, capex and depreciation are DERIVED as H1 less Q2. All cross-check against the TTM Mar'26 column.
B29: ="• TTM (Jun'26) D&A of "&TEXT($G$7,"#,##0")&" is DERIVED as FY2025 + H1'26 - H1'25, all on the cash-flow 'depreciation of property and equipment' basis. VERIFIED to the Q2 2026 10-Q: "&"H1'25 "&TEXT($F$22,"#,##0")&" and H1'26 "&TEXT($G$22,"#,##0")&" match the filed statement exactly. The earlier mixed-basis concern is resolved - the figure excludes amortisation of intangibles, so the label 'D&A' is strictly 'depreciation'." -> • TTM (Jun'26) D&A of 25,237 is DERIVED as FY2025 + H1'26 - H1'25, all on the cash-flow 'depreciation of property and equipment' basis. VERIFIED to the Q2 2026 10-Q: H1'25 9,485 and H1'26 13,586 match the filed statement exactly. The earlier mixed-basis concern is resolved - the figure excludes amortisation of intangibles, so the label 'D&A' is strictly 'depreciation'.
B30: ="• Capex guidance: FY2026 raised to 195,000-205,000 from 180,000-190,000. H1 capex was "&TEXT(-$G$20,"#,##0")&", so guidance implies 114,000-124,000 in H2 alone." -> • Capex guidance: FY2026 raised to 195,000-205,000 from 180,000-190,000. H1 capex was 80,598, so guidance implies 114,000-124,000 in H2 alone.
B31: • FY2027 capex guided 'significantly' higher, no dollar figure, and NO capex peak timeline was given on the Q2 call.
B32: • Buybacks suspended from Q1 2026. Dividends initiated Apr 2024, ~10,000/yr.
B33: ="• Stock-based compensation: "&"H1'25 "&TEXT($F$23,"#,##0")&" and H1'26 "&TEXT($G$23,"#,##0")&" are filed cash-flow figures from the Q2 2026 10-Q. TTM Jun'26 of "&TEXT($G$8,"#,##0")&" is derived on the same FY2025 + H1'26 - H1'25 convention. The 10-Q reports SBC only on a six-month basis in the cash flow statement, so no Q2'26 or Q1'26 split is available." -> • Stock-based compensation: H1'25 11,514 and H1'26 14,708 are filed cash-flow figures from the Q2 2026 10-Q. TTM Jun'26 of 28,147 is derived on the same FY2025 + H1'26 - H1'25 convention. The 10-Q reports SBC only on a six-month basis in the cash flow statement, so no Q2'26 or Q1'26 split is available.

Sheet 10 Guidance and Quotes
B2: 10 — CAPEX GUIDANCE TRAIL AND MANAGEMENT QUOTES
B3: Quotes verbatim from the Q2 2026 earnings call, July 22, 2026.
B5: Item | C5: Guidance
B6: FY2025 capex actual | C6: 91,447
B7: FY2026 capex - initial guide (Q4'25 call) | C7: 175,000 - 185,000
B8: FY2026 capex - raised (Q1'26 call, for Intersect) | C8: 180,000 - 190,000
B9: FY2026 capex - raised again (Q2'26 call) | C9: 195,000 - 205,000
B10: H1 2026 capex actual | C10: 80,598
B11: Implied H2 2026 capex | C11: 114,000 - 124,000
B12: FY2027 capex | C12: 'increase significantly', no dollar figure
B13: Capex peak timeline | C13: NONE GIVEN
B15: Verbatim quotes
B16: Speaker / topic | C16: Quote
B17: Ashkenazi - 2027 capex | C17: "we continue to expect our CapEx to increase significantly in 2027 and will provide more details at a later date."
B18: Ashkenazi - free cash flow | C18: "we expect the free cash flow will remain under pressure, driven by our investments in technical infrastructure, which enables us to capitalize on the AI opportunity and continue to drive attractive returns."
